<sdf version='1.6'>
  <world name='default'>
    <model name='labrob_ground'>
      <static>1</static>
      <link name='link'>
        <collision name='collision'>
          <geometry>
            <plane>
              <normal>0 0 1</normal>
              <size>20 20</size>
            </plane>
          </geometry>
          <surface>
            <contact>
              <collide_bitmask>2</collide_bitmask>
              <ode/>
            </contact>
            <bounce/>
            <friction>
              <torsional>
                <ode/>
              </torsional>
              <ode/>
            </friction>
          </surface>
          <max_contacts>10</max_contacts>
        </collision>
        <visual name='visual'>
          <cast_shadows>0</cast_shadows>
          <geometry>
            <plane>
              <normal>0 0 1</normal>
              <size>20 20</size>
            </plane>
          </geometry>
          <material>
            <script>
              <uri>model://labrob_ground/materials/scripts/</uri>
              <uri>model://labrob_ground/materials/textures/</uri>
              <name>Labrob/AsphaltGround</name>
            </script>
          </material>
        </visual>
        <self_collide>0</self_collide>
        <kinematic>0</kinematic>
      </link>
      <pose frame=''>0 0 0 0 -0 0</pose>
    </model>
    <light name='sun' type='directional'>
      <cast_shadows>1</cast_shadows>
      <pose frame=''>0 0 10 0 -0 0</pose>
      <diffuse>0.8 0.8 0.8 1</diffuse>
      <specular>0.2 0.2 0.2 1</specular>
      <attenuation>
        <range>1000</range>
        <constant>0.9</constant>
        <linear>0.01</linear>
        <quadratic>0.001</quadratic>
      </attenuation>
      <direction>-0.5 0.1 -0.9</direction>
    </light>
    <model name='borders'>
      <static>1</static>
      <link name='chassis_pos_x'>
        <pose frame=''>10 0 0.35 0 -0 1.57079</pose>
        <collision name='collision_pos_x'>
          <geometry>
            <box>
              <size>20 0.05 0.7</size>
            </box>
          </geometry>
          <max_contacts>10</max_contacts>
          <surface>
            <contact>
              <ode/>
            </contact>
            <bounce/>
            <friction>
              <torsional>
                <ode/>
              </torsional>
              <ode/>
            </friction>
          </surface>
        </collision>
        <visual name='visual'>
          <geometry>
            <box>
              <size>20 0.05 0.7</size>
            </box>
          </geometry>
          <material>
            <ambient>0.1 0.1 0.1 1</ambient>
            <diffuse>0.1 0.1 0.1 1</diffuse>
            <specular>0.1 0.1 0.1 1</specular>
            <emissive>0 0 0 0</emissive>
          </material>
        </visual>
        <sensor name='contact_sensor_1' type='contact'>
          <plugin name='my_contact_plugin' filename='libgazebo_ros_bumper.so'>
            <bumperTopicName>border_bumper</bumperTopicName>
            <frameName>world</frameName>
          </plugin>
          <contact>
            <collision>collision_pos_x</collision>
            <topic>__default_topic__</topic>
          </contact>
        </sensor>
        <self_collide>0</self_collide>
        <kinematic>0</kinematic>
      </link>
      <link name='chassis_neg_x'>
        <pose frame=''>-10 0 0.35 0 -0 1.57079</pose>
        <collision name='collision_neg_x'>
          <geometry>
            <box>
              <size>20 0.05 0.7</size>
            </box>
          </geometry>
          <max_contacts>10</max_contacts>
          <surface>
            <contact>
              <ode/>
            </contact>
            <bounce/>
            <friction>
              <torsional>
                <ode/>
              </torsional>
              <ode/>
            </friction>
          </surface>
        </collision>
        <visual name='visual'>
          <geometry>
            <box>
              <size>20 0.05 0.7</size>
            </box>
          </geometry>
          <material>
            <ambient>0.1 0.1 0.1 1</ambient>
            <diffuse>0.1 0.1 0.1 1</diffuse>
            <specular>0.1 0.1 0.1 1</specular>
            <emissive>0 0 0 0</emissive>
          </material>
        </visual>
        <sensor name='contact_sensor_2' type='contact'>
          <plugin name='my_contact_plugin' filename='libgazebo_ros_bumper.so'>
            <bumperTopicName>border_bumper</bumperTopicName>
            <frameName>world</frameName>
          </plugin>
          <contact>
            <collision>collision_neg_x</collision>
            <topic>__default_topic__</topic>
          </contact>
        </sensor>
        <self_collide>0</self_collide>
        <kinematic>0</kinematic>
      </link>
      <link name='chassis_pos_y'>
        <pose frame=''>0 10 0.35 0 -0 0</pose>
        <collision name='collision_pos_y'>
          <geometry>
            <box>
              <size>20 0.05 0.7</size>
            </box>
          </geometry>
          <max_contacts>10</max_contacts>
          <surface>
            <contact>
              <ode/>
            </contact>
            <bounce/>
            <friction>
              <torsional>
                <ode/>
              </torsional>
              <ode/>
            </friction>
          </surface>
        </collision>
        <visual name='visual'>
          <geometry>
            <box>
              <size>20 0.05 0.7</size>
            </box>
          </geometry>
          <material>
            <ambient>0.1 0.1 0.1 1</ambient>
            <diffuse>0.1 0.1 0.1 1</diffuse>
            <specular>0.1 0.1 0.1 1</specular>
            <emissive>0 0 0 0</emissive>
          </material>
        </visual>
        <sensor name='contact_sensor_3' type='contact'>
          <plugin name='my_contact_plugin' filename='libgazebo_ros_bumper.so'>
            <bumperTopicName>border_bumper</bumperTopicName>
            <frameName>world</frameName>
          </plugin>
          <contact>
            <collision>collision_pos_y</collision>
            <topic>__default_topic__</topic>
          </contact>
        </sensor>
        <self_collide>0</self_collide>
        <kinematic>0</kinematic>
      </link>
      <link name='chassis_neg_y'>
        <pose frame=''>0 -10 0.35 0 -0 0</pose>
        <collision name='collision_neg_y'>
          <geometry>
            <box>
              <size>20 0.05 0.7</size>
            </box>
          </geometry>
          <max_contacts>10</max_contacts>
          <surface>
            <contact>
              <ode/>
            </contact>
            <bounce/>
            <friction>
              <torsional>
                <ode/>
              </torsional>
              <ode/>
            </friction>
          </surface>
        </collision>
        <visual name='visual'>
          <geometry>
            <box>
              <size>20 0.05 0.7</size>
            </box>
          </geometry>
          <material>
            <ambient>0.1 0.1 0.1 1</ambient>
            <diffuse>0.1 0.1 0.1 1</diffuse>
            <specular>0.1 0.1 0.1 1</specular>
            <emissive>0 0 0 0</emissive>
          </material>
        </visual>
        <sensor name='contact_sensor_4' type='contact'>
          <plugin name='my_contact_plugin' filename='libgazebo_ros_bumper.so'>
            <bumperTopicName>border_bumper</bumperTopicName>
            <frameName>world</frameName>
          </plugin>
          <contact>
            <collision>collision_neg_y</collision>
            <topic>__default_topic__</topic>
          </contact>
        </sensor>
        <self_collide>0</self_collide>
        <kinematic>0</kinematic>
      </link>
      <pose frame=''>0 0 0 0 -0 0</pose>
    </model>
    <gravity>0 0 -9.8</gravity>
    <magnetic_field>6e-06 2.3e-05 -4.2e-05</magnetic_field>
    <atmosphere type='adiabatic'/>
    <physics name='default_physics' default='0' type='ode'>
      <max_step_size>0.001</max_step_size>
      <real_time_factor>1</real_time_factor>
      <real_time_update_rate>1000</real_time_update_rate>
    </physics>
    <scene>
      <ambient>0.4 0.4 0.4 1</ambient>
      <background>0.7 0.7 0.7 1</background>
      <shadows>1</shadows>
    </scene>
    <spherical_coordinates>
      <surface_model>EARTH_WGS84</surface_model>
      <latitude_deg>0</latitude_deg>
      <longitude_deg>0</longitude_deg>
      <elevation>0</elevation>
      <heading_deg>0</heading_deg>
    </spherical_coordinates>
    <model name='coin_0'>
      <link name='chassis'>
        <pose frame=''>0 0 0.26 0 -0 0</pose>
        <collision name='box_collision'>
          <geometry>
            <sphere>
              <radius>0.25</radius>
            </sphere>
          </geometry>
          <surface>
            <contact>
              <collide_bitmask>1</collide_bitmask>
              <ode>
                <min_depth>10</min_depth>
                <kp>1</kp>
              </ode>
            </contact>
            <bounce/>
            <friction>
              <torsional>
                <ode/>
              </torsional>
              <ode/>
            </friction>
          </surface>
          <max_contacts>10</max_contacts>
        </collision>
        <visual name='visual'>
          <pose frame=''>0 0 0 0 1.57 0</pose>
          <geometry>
            <cylinder>
              <radius>0.25</radius>
              <length>0.1</length>
            </cylinder>
          </geometry>
          <material>
            <ambient>1 1 0 1</ambient>
            <diffuse>1 1 0 1</diffuse>
            <specular>0.1 0.1 0.1 1</specular>
            <emissive>0 0 0 0</emissive>
          </material>
        </visual>
        <sensor name='contact_sensor_1' type='contact'>
          <plugin name='my_contact_plugin' filename='libgazebo_ros_bumper.so'>
            <bumperTopicName>coin_bumper</bumperTopicName>
            <frameName>world</frameName>
          </plugin>
          <contact>
            <collision>box_collision</collision>
            <topic>__default_topic__</topic>
          </contact>
        </sensor>
        <self_collide>0</self_collide>
        <inertial>
          <inertia>
            <ixx>1</ixx>
            <ixy>0</ixy>
            <ixz>0</ixz>
            <iyy>1</iyy>
            <iyz>0</iyz>
            <izz>1</izz>
          </inertia>
          <mass>1</mass>
        </inertial>
        <kinematic>0</kinematic>
      </link>
      <joint name='coin_hinge' type='revolute'>
        <pose frame=''>0 0 0.26 0 -0 0</pose>
        <child>chassis</child>
        <parent>world</parent>
        <axis>
          <xyz>0 0 1</xyz>
          <use_parent_model_frame>1</use_parent_model_frame>
          <limit>
            <lower>-1e+16</lower>
            <upper>1e+16</upper>
          </limit>
          <dynamics>
            <spring_reference>0</spring_reference>
            <spring_stiffness>0</spring_stiffness>
          </dynamics>
        </axis>
      </joint>
      <pose frame=''>0.179485 -1.53193 0 0 -0 0</pose>
    </model>
    <model name='coin_1'>
      <link name='chassis'>
        <pose frame=''>0 0 0.26 0 -0 0</pose>
        <collision name='box_collision'>
          <geometry>
            <sphere>
              <radius>0.25</radius>
            </sphere>
          </geometry>
          <surface>
            <contact>
              <collide_bitmask>1</collide_bitmask>
              <ode>
                <min_depth>10</min_depth>
                <kp>1</kp>
              </ode>
            </contact>
            <bounce/>
            <friction>
              <torsional>
                <ode/>
              </torsional>
              <ode/>
            </friction>
          </surface>
          <max_contacts>10</max_contacts>
        </collision>
        <visual name='visual'>
          <pose frame=''>0 0 0 0 1.57 0</pose>
          <geometry>
            <cylinder>
              <radius>0.25</radius>
              <length>0.1</length>
            </cylinder>
          </geometry>
          <material>
            <ambient>1 1 0 1</ambient>
            <diffuse>1 1 0 1</diffuse>
            <specular>0.1 0.1 0.1 1</specular>
            <emissive>0 0 0 0</emissive>
          </material>
        </visual>
        <sensor name='contact_sensor_1' type='contact'>
          <plugin name='my_contact_plugin' filename='libgazebo_ros_bumper.so'>
            <bumperTopicName>coin_bumper</bumperTopicName>
            <frameName>world</frameName>
          </plugin>
          <contact>
            <collision>box_collision</collision>
            <topic>__default_topic__</topic>
          </contact>
        </sensor>
        <self_collide>0</self_collide>
        <inertial>
          <inertia>
            <ixx>1</ixx>
            <ixy>0</ixy>
            <ixz>0</ixz>
            <iyy>1</iyy>
            <iyz>0</iyz>
            <izz>1</izz>
          </inertia>
          <mass>1</mass>
        </inertial>
        <kinematic>0</kinematic>
      </link>
      <joint name='coin_hinge' type='revolute'>
        <pose frame=''>0 0 0.26 0 -0 0</pose>
        <child>chassis</child>
        <parent>world</parent>
        <axis>
          <xyz>0 0 1</xyz>
          <use_parent_model_frame>1</use_parent_model_frame>
          <limit>
            <lower>-1e+16</lower>
            <upper>1e+16</upper>
          </limit>
          <dynamics>
            <spring_reference>0</spring_reference>
            <spring_stiffness>0</spring_stiffness>
          </dynamics>
        </axis>
      </joint>
      <pose frame=''>1.76429 -4.46358 0 0 -0 0</pose>
    </model>
    <model name='coin_2'>
      <link name='chassis'>
        <pose frame=''>0 0 0.26 0 -0 0</pose>
        <collision name='box_collision'>
          <geometry>
            <sphere>
              <radius>0.25</radius>
            </sphere>
          </geometry>
          <surface>
            <contact>
              <collide_bitmask>1</collide_bitmask>
              <ode>
                <min_depth>10</min_depth>
                <kp>1</kp>
              </ode>
            </contact>
            <bounce/>
            <friction>
              <torsional>
                <ode/>
              </torsional>
              <ode/>
            </friction>
          </surface>
          <max_contacts>10</max_contacts>
        </collision>
        <visual name='visual'>
          <pose frame=''>0 0 0 0 1.57 0</pose>
          <geometry>
            <cylinder>
              <radius>0.25</radius>
              <length>0.1</length>
            </cylinder>
          </geometry>
          <material>
            <ambient>1 1 0 1</ambient>
            <diffuse>1 1 0 1</diffuse>
            <specular>0.1 0.1 0.1 1</specular>
            <emissive>0 0 0 0</emissive>
          </material>
        </visual>
        <sensor name='contact_sensor_1' type='contact'>
          <plugin name='my_contact_plugin' filename='libgazebo_ros_bumper.so'>
            <bumperTopicName>coin_bumper</bumperTopicName>
            <frameName>world</frameName>
          </plugin>
          <contact>
            <collision>box_collision</collision>
            <topic>__default_topic__</topic>
          </contact>
        </sensor>
        <self_collide>0</self_collide>
        <inertial>
          <inertia>
            <ixx>1</ixx>
            <ixy>0</ixy>
            <ixz>0</ixz>
            <iyy>1</iyy>
            <iyz>0</iyz>
            <izz>1</izz>
          </inertia>
          <mass>1</mass>
        </inertial>
        <kinematic>0</kinematic>
      </link>
      <joint name='coin_hinge' type='revolute'>
        <pose frame=''>0 0 0.26 0 -0 0</pose>
        <child>chassis</child>
        <parent>world</parent>
        <axis>
          <xyz>0 0 1</xyz>
          <use_parent_model_frame>1</use_parent_model_frame>
          <limit>
            <lower>-1e+16</lower>
            <upper>1e+16</upper>
          </limit>
          <dynamics>
            <spring_reference>0</spring_reference>
            <spring_stiffness>0</spring_stiffness>
          </dynamics>
        </axis>
      </joint>
      <pose frame=''>5.98475 -4.69508 0 0 -0 0</pose>
    </model>
    <model name='coin_3'>
      <link name='chassis'>
        <pose frame=''>0 0 0.26 0 -0 0</pose>
        <collision name='box_collision'>
          <geometry>
            <sphere>
              <radius>0.25</radius>
            </sphere>
          </geometry>
          <surface>
            <contact>
              <collide_bitmask>1</collide_bitmask>
              <ode>
                <min_depth>10</min_depth>
                <kp>1</kp>
              </ode>
            </contact>
            <bounce/>
            <friction>
              <torsional>
                <ode/>
              </torsional>
              <ode/>
            </friction>
          </surface>
          <max_contacts>10</max_contacts>
        </collision>
        <visual name='visual'>
          <pose frame=''>0 0 0 0 1.57 0</pose>
          <geometry>
            <cylinder>
              <radius>0.25</radius>
              <length>0.1</length>
            </cylinder>
          </geometry>
          <material>
            <ambient>1 1 0 1</ambient>
            <diffuse>1 1 0 1</diffuse>
            <specular>0.1 0.1 0.1 1</specular>
            <emissive>0 0 0 0</emissive>
          </material>
        </visual>
        <sensor name='contact_sensor_1' type='contact'>
          <plugin name='my_contact_plugin' filename='libgazebo_ros_bumper.so'>
            <bumperTopicName>coin_bumper</bumperTopicName>
            <frameName>world</frameName>
          </plugin>
          <contact>
            <collision>box_collision</collision>
            <topic>__default_topic__</topic>
          </contact>
        </sensor>
        <self_collide>0</self_collide>
        <inertial>
          <inertia>
            <ixx>1</ixx>
            <ixy>0</ixy>
            <ixz>0</ixz>
            <iyy>1</iyy>
            <iyz>0</iyz>
            <izz>1</izz>
          </inertia>
          <mass>1</mass>
        </inertial>
        <kinematic>0</kinematic>
      </link>
      <joint name='coin_hinge' type='revolute'>
        <pose frame=''>0 0 0.26 0 -0 0</pose>
        <child>chassis</child>
        <parent>world</parent>
        <axis>
          <xyz>0 0 1</xyz>
          <use_parent_model_frame>1</use_parent_model_frame>
          <limit>
            <lower>-1e+16</lower>
            <upper>1e+16</upper>
          </limit>
          <dynamics>
            <spring_reference>0</spring_reference>
            <spring_stiffness>0</spring_stiffness>
          </dynamics>
        </axis>
      </joint>
      <pose frame=''>-4.69873 -5.44036 0 0 -0 0</pose>
    </model>
    <model name='coin_6'>
      <link name='chassis'>
        <pose frame=''>0 0 0.26 0 -0 0</pose>
        <collision name='box_collision'>
          <geometry>
            <sphere>
              <radius>0.25</radius>
            </sphere>
          </geometry>
          <surface>
            <contact>
              <collide_bitmask>1</collide_bitmask>
              <ode>
                <min_depth>10</min_depth>
                <kp>1</kp>
              </ode>
            </contact>
            <bounce/>
            <friction>
              <torsional>
                <ode/>
              </torsional>
              <ode/>
            </friction>
          </surface>
          <max_contacts>10</max_contacts>
        </collision>
        <visual name='visual'>
          <pose frame=''>0 0 0 0 1.57 0</pose>
          <geometry>
            <cylinder>
              <radius>0.25</radius>
              <length>0.1</length>
            </cylinder>
          </geometry>
          <material>
            <ambient>1 1 0 1</ambient>
            <diffuse>1 1 0 1</diffuse>
            <specular>0.1 0.1 0.1 1</specular>
            <emissive>0 0 0 0</emissive>
          </material>
        </visual>
        <sensor name='contact_sensor_1' type='contact'>
          <plugin name='my_contact_plugin' filename='libgazebo_ros_bumper.so'>
            <bumperTopicName>coin_bumper</bumperTopicName>
            <frameName>world</frameName>
          </plugin>
          <contact>
            <collision>box_collision</collision>
            <topic>__default_topic__</topic>
          </contact>
        </sensor>
        <self_collide>0</self_collide>
        <inertial>
          <inertia>
            <ixx>1</ixx>
            <ixy>0</ixy>
            <ixz>0</ixz>
            <iyy>1</iyy>
            <iyz>0</iyz>
            <izz>1</izz>
          </inertia>
          <mass>1</mass>
        </inertial>
        <kinematic>0</kinematic>
      </link>
      <joint name='coin_hinge' type='revolute'>
        <pose frame=''>0 0 0.26 0 -0 0</pose>
        <child>chassis</child>
        <parent>world</parent>
        <axis>
          <xyz>0 0 1</xyz>
          <use_parent_model_frame>1</use_parent_model_frame>
          <limit>
            <lower>-1e+16</lower>
            <upper>1e+16</upper>
          </limit>
          <dynamics>
            <spring_reference>0</spring_reference>
            <spring_stiffness>0</spring_stiffness>
          </dynamics>
        </axis>
      </joint>
      <pose frame=''>-4.94528 8.82124 0 0 -0 0</pose>
    </model>
    <model name='coin_7'>
      <link name='chassis'>
        <pose frame=''>0 0 0.26 0 -0 0</pose>
        <collision name='box_collision'>
          <geometry>
            <sphere>
              <radius>0.25</radius>
            </sphere>
          </geometry>
          <surface>
            <contact>
              <collide_bitmask>1</collide_bitmask>
              <ode>
                <min_depth>10</min_depth>
                <kp>1</kp>
              </ode>
            </contact>
            <bounce/>
            <friction>
              <torsional>
                <ode/>
              </torsional>
              <ode/>
            </friction>
          </surface>
          <max_contacts>10</max_contacts>
        </collision>
        <visual name='visual'>
          <pose frame=''>0 0 0 0 1.57 0</pose>
          <geometry>
            <cylinder>
              <radius>0.25</radius>
              <length>0.1</length>
            </cylinder>
          </geometry>
          <material>
            <ambient>1 1 0 1</ambient>
            <diffuse>1 1 0 1</diffuse>
            <specular>0.1 0.1 0.1 1</specular>
            <emissive>0 0 0 0</emissive>
          </material>
        </visual>
        <sensor name='contact_sensor_1' type='contact'>
          <plugin name='my_contact_plugin' filename='libgazebo_ros_bumper.so'>
            <bumperTopicName>coin_bumper</bumperTopicName>
            <frameName>world</frameName>
          </plugin>
          <contact>
            <collision>box_collision</collision>
            <topic>__default_topic__</topic>
          </contact>
        </sensor>
        <self_collide>0</self_collide>
        <inertial>
          <inertia>
            <ixx>1</ixx>
            <ixy>0</ixy>
            <ixz>0</ixz>
            <iyy>1</iyy>
            <iyz>0</iyz>
            <izz>1</izz>
          </inertia>
          <mass>1</mass>
        </inertial>
        <kinematic>0</kinematic>
      </link>
      <joint name='coin_hinge' type='revolute'>
        <pose frame=''>0 0 0.26 0 -0 0</pose>
        <child>chassis</child>
        <parent>world</parent>
        <axis>
          <xyz>0 0 1</xyz>
          <use_parent_model_frame>1</use_parent_model_frame>
          <limit>
            <lower>-1e+16</lower>
            <upper>1e+16</upper>
          </limit>
          <dynamics>
            <spring_reference>0</spring_reference>
            <spring_stiffness>0</spring_stiffness>
          </dynamics>
        </axis>
      </joint>
      <pose frame=''>-0.293643 3.28118 0 0 -0 0</pose>
    </model>
    <model name='coin_8'>
      <link name='chassis'>
        <pose frame=''>0 0 0.26 0 -0 0</pose>
        <collision name='box_collision'>
          <geometry>
            <sphere>
              <radius>0.25</radius>
            </sphere>
          </geometry>
          <surface>
            <contact>
              <collide_bitmask>1</collide_bitmask>
              <ode>
                <min_depth>10</min_depth>
                <kp>1</kp>
              </ode>
            </contact>
            <bounce/>
            <friction>
              <torsional>
                <ode/>
              </torsional>
              <ode/>
            </friction>
          </surface>
          <max_contacts>10</max_contacts>
        </collision>
        <visual name='visual'>
          <pose frame=''>0 0 0 0 1.57 0</pose>
          <geometry>
            <cylinder>
              <radius>0.25</radius>
              <length>0.1</length>
            </cylinder>
          </geometry>
          <material>
            <ambient>1 1 0 1</ambient>
            <diffuse>1 1 0 1</diffuse>
            <specular>0.1 0.1 0.1 1</specular>
            <emissive>0 0 0 0</emissive>
          </material>
        </visual>
        <sensor name='contact_sensor_1' type='contact'>
          <plugin name='my_contact_plugin' filename='libgazebo_ros_bumper.so'>
            <bumperTopicName>coin_bumper</bumperTopicName>
            <frameName>world</frameName>
          </plugin>
          <contact>
            <collision>box_collision</collision>
            <topic>__default_topic__</topic>
          </contact>
        </sensor>
        <self_collide>0</self_collide>
        <inertial>
          <inertia>
            <ixx>1</ixx>
            <ixy>0</ixy>
            <ixz>0</ixz>
            <iyy>1</iyy>
            <iyz>0</iyz>
            <izz>1</izz>
          </inertia>
          <mass>1</mass>
        </inertial>
        <kinematic>0</kinematic>
      </link>
      <joint name='coin_hinge' type='revolute'>
        <pose frame=''>0 0 0.26 0 -0 0</pose>
        <child>chassis</child>
        <parent>world</parent>
        <axis>
          <xyz>0 0 1</xyz>
          <use_parent_model_frame>1</use_parent_model_frame>
          <limit>
            <lower>-1e+16</lower>
            <upper>1e+16</upper>
          </limit>
          <dynamics>
            <spring_reference>0</spring_reference>
            <spring_stiffness>0</spring_stiffness>
          </dynamics>
        </axis>
      </joint>
      <pose frame=''>7.4107 7.5913 0 0 -0 0</pose>
    </model>
    <model name='coin_9'>
      <link name='chassis'>
        <pose frame=''>0 0 0.26 0 -0 0</pose>
        <collision name='box_collision'>
          <geometry>
            <sphere>
              <radius>0.25</radius>
            </sphere>
          </geometry>
          <surface>
            <contact>
              <collide_bitmask>1</collide_bitmask>
              <ode>
                <min_depth>10</min_depth>
                <kp>1</kp>
              </ode>
            </contact>
            <bounce/>
            <friction>
              <torsional>
                <ode/>
              </torsional>
              <ode/>
            </friction>
          </surface>
          <max_contacts>10</max_contacts>
        </collision>
        <visual name='visual'>
          <pose frame=''>0 0 0 0 1.57 0</pose>
          <geometry>
            <cylinder>
              <radius>0.25</radius>
              <length>0.1</length>
            </cylinder>
          </geometry>
          <material>
            <ambient>1 1 0 1</ambient>
            <diffuse>1 1 0 1</diffuse>
            <specular>0.1 0.1 0.1 1</specular>
            <emissive>0 0 0 0</emissive>
          </material>
        </visual>
        <sensor name='contact_sensor_1' type='contact'>
          <plugin name='my_contact_plugin' filename='libgazebo_ros_bumper.so'>
            <bumperTopicName>coin_bumper</bumperTopicName>
            <frameName>world</frameName>
          </plugin>
          <contact>
            <collision>box_collision</collision>
            <topic>__default_topic__</topic>
          </contact>
        </sensor>
        <self_collide>0</self_collide>
        <inertial>
          <inertia>
            <ixx>1</ixx>
            <ixy>0</ixy>
            <ixz>0</ixz>
            <iyy>1</iyy>
            <iyz>0</iyz>
            <izz>1</izz>
          </inertia>
          <mass>1</mass>
        </inertial>
        <kinematic>0</kinematic>
      </link>
      <joint name='coin_hinge' type='revolute'>
        <pose frame=''>0 0 0.26 0 -0 0</pose>
        <child>chassis</child>
        <parent>world</parent>
        <axis>
          <xyz>0 0 1</xyz>
          <use_parent_model_frame>1</use_parent_model_frame>
          <limit>
            <lower>-1e+16</lower>
            <upper>1e+16</upper>
          </limit>
          <dynamics>
            <spring_reference>0</spring_reference>
            <spring_stiffness>0</spring_stiffness>
          </dynamics>
        </axis>
      </joint>
      <pose frame=''>2.96582 0.086113 0 0 -0 0</pose>
    </model>
    <model name='bomb_0'>
      <link name='chassis'>
        <pose frame=''>0 0 0.25 0 -0 0</pose>
        <collision name='box_collision'>
          <geometry>
            <sphere>
              <radius>0.25</radius>
            </sphere>
          </geometry>
          <surface>
            <contact>
              <collide_bitmask>1</collide_bitmask>
              <ode>
                <min_depth>10</min_depth>
                <kp>1</kp>
              </ode>
            </contact>
            <bounce/>
            <friction>
              <torsional>
                <ode/>
              </torsional>
              <ode/>
            </friction>
          </surface>
          <max_contacts>10</max_contacts>
        </collision>
        <visual name='visual'>
          <pose frame=''>0 0 0.2 0 -0 0</pose>
          <geometry>
            <cylinder>
              <radius>0.1</radius>
              <length>0.2</length>
            </cylinder>
          </geometry>
          <material>
            <ambient>0 0 0 1</ambient>
            <diffuse>0 0 0 1</diffuse>
            <specular>0.1 0.1 0.1 1</specular>
            <emissive>0 0 0 0</emissive>
          </material>
        </visual>
        <visual name='visual2'>
          <geometry>
            <sphere>
              <radius>0.25</radius>
            </sphere>
          </geometry>
          <material>
            <ambient>0 0 0 1</ambient>
            <diffuse>0 0 0 1</diffuse>
            <specular>0.1 0.1 0.1 1</specular>
            <emissive>0 0 0 0</emissive>
          </material>
        </visual>
        <visual name='visual3'>
          <pose frame=''>0 0 0.3 0 -0 0</pose>
          <geometry>
            <cylinder>
              <radius>0.01</radius>
              <length>0.2</length>
            </cylinder>
          </geometry>
          <material>
            <ambient>1 1 1 1</ambient>
            <diffuse>1 1 1 1</diffuse>
            <specular>0.1 0.1 0.1 1</specular>
            <emissive>0 0 0 0</emissive>
          </material>
        </visual>
        <sensor name='contact_sensor_1' type='contact'>
          <plugin name='my_contact_plugin' filename='libgazebo_ros_bumper.so'>
            <bumperTopicName>bomb_bumper</bumperTopicName>
            <frameName>world</frameName>
          </plugin>
          <contact>
            <collision>box_collision</collision>
            <topic>__default_topic__</topic>
          </contact>
        </sensor>
        <self_collide>0</self_collide>
        <inertial>
          <inertia>
            <ixx>1</ixx>
            <ixy>0</ixy>
            <ixz>0</ixz>
            <iyy>1</iyy>
            <iyz>0</iyz>
            <izz>1</izz>
          </inertia>
          <mass>1</mass>
        </inertial>
        <kinematic>0</kinematic>
      </link>
      <joint name='bomb_hinge' type='revolute'>
        <pose frame=''>0 0 0.2 0 -0 0</pose>
        <child>chassis</child>
        <parent>world</parent>
        <axis>
          <xyz>0 0 0</xyz>
          <use_parent_model_frame>1</use_parent_model_frame>
          <limit>
            <lower>-1e+16</lower>
            <upper>1e+16</upper>
          </limit>
          <dynamics>
            <spring_reference>0</spring_reference>
            <spring_stiffness>0</spring_stiffness>
          </dynamics>
        </axis>
      </joint>
      <pose frame=''>8.72929 -6.70741 0 0 -0 0</pose>
    </model>
    <model name='bomb_1'>
      <link name='chassis'>
        <pose frame=''>0 0 0.25 0 -0 0</pose>
        <collision name='box_collision'>
          <geometry>
            <sphere>
              <radius>0.25</radius>
            </sphere>
          </geometry>
          <surface>
            <contact>
              <collide_bitmask>1</collide_bitmask>
              <ode>
                <min_depth>10</min_depth>
                <kp>1</kp>
              </ode>
            </contact>
            <bounce/>
            <friction>
              <torsional>
                <ode/>
              </torsional>
              <ode/>
            </friction>
          </surface>
          <max_contacts>10</max_contacts>
        </collision>
        <visual name='visual'>
          <pose frame=''>0 0 0.2 0 -0 0</pose>
          <geometry>
            <cylinder>
              <radius>0.1</radius>
              <length>0.2</length>
            </cylinder>
          </geometry>
          <material>
            <ambient>0 0 0 1</ambient>
            <diffuse>0 0 0 1</diffuse>
            <specular>0.1 0.1 0.1 1</specular>
            <emissive>0 0 0 0</emissive>
          </material>
        </visual>
        <visual name='visual2'>
          <geometry>
            <sphere>
              <radius>0.25</radius>
            </sphere>
          </geometry>
          <material>
            <ambient>0 0 0 1</ambient>
            <diffuse>0 0 0 1</diffuse>
            <specular>0.1 0.1 0.1 1</specular>
            <emissive>0 0 0 0</emissive>
          </material>
        </visual>
        <visual name='visual3'>
          <pose frame=''>0 0 0.3 0 -0 0</pose>
          <geometry>
            <cylinder>
              <radius>0.01</radius>
              <length>0.2</length>
            </cylinder>
          </geometry>
          <material>
            <ambient>1 1 1 1</ambient>
            <diffuse>1 1 1 1</diffuse>
            <specular>0.1 0.1 0.1 1</specular>
            <emissive>0 0 0 0</emissive>
          </material>
        </visual>
        <sensor name='contact_sensor_1' type='contact'>
          <plugin name='my_contact_plugin' filename='libgazebo_ros_bumper.so'>
            <bumperTopicName>bomb_bumper</bumperTopicName>
            <frameName>world</frameName>
          </plugin>
          <contact>
            <collision>box_collision</collision>
            <topic>__default_topic__</topic>
          </contact>
        </sensor>
        <self_collide>0</self_collide>
        <inertial>
          <inertia>
            <ixx>1</ixx>
            <ixy>0</ixy>
            <ixz>0</ixz>
            <iyy>1</iyy>
            <iyz>0</iyz>
            <izz>1</izz>
          </inertia>
          <mass>1</mass>
        </inertial>
        <kinematic>0</kinematic>
      </link>
      <joint name='bomb_hinge' type='revolute'>
        <pose frame=''>0 0 0.2 0 -0 0</pose>
        <child>chassis</child>
        <parent>world</parent>
        <axis>
          <xyz>0 0 0</xyz>
          <use_parent_model_frame>1</use_parent_model_frame>
          <limit>
            <lower>-1e+16</lower>
            <upper>1e+16</upper>
          </limit>
          <dynamics>
            <spring_reference>0</spring_reference>
            <spring_stiffness>0</spring_stiffness>
          </dynamics>
        </axis>
      </joint>
      <pose frame=''>-6.34067 -8.50834 0 0 -0 0</pose>
    </model>
    <model name='bomb_3'>
      <link name='chassis'>
        <pose frame=''>0 0 0.25 0 -0 0</pose>
        <collision name='box_collision'>
          <geometry>
            <sphere>
              <radius>0.25</radius>
            </sphere>
          </geometry>
          <surface>
            <contact>
              <collide_bitmask>1</collide_bitmask>
              <ode>
                <min_depth>10</min_depth>
                <kp>1</kp>
              </ode>
            </contact>
            <bounce/>
            <friction>
              <torsional>
                <ode/>
              </torsional>
              <ode/>
            </friction>
          </surface>
          <max_contacts>10</max_contacts>
        </collision>
        <visual name='visual'>
          <pose frame=''>0 0 0.2 0 -0 0</pose>
          <geometry>
            <cylinder>
              <radius>0.1</radius>
              <length>0.2</length>
            </cylinder>
          </geometry>
          <material>
            <ambient>0 0 0 1</ambient>
            <diffuse>0 0 0 1</diffuse>
            <specular>0.1 0.1 0.1 1</specular>
            <emissive>0 0 0 0</emissive>
          </material>
        </visual>
        <visual name='visual2'>
          <geometry>
            <sphere>
              <radius>0.25</radius>
            </sphere>
          </geometry>
          <material>
            <ambient>0 0 0 1</ambient>
            <diffuse>0 0 0 1</diffuse>
            <specular>0.1 0.1 0.1 1</specular>
            <emissive>0 0 0 0</emissive>
          </material>
        </visual>
        <visual name='visual3'>
          <pose frame=''>0 0 0.3 0 -0 0</pose>
          <geometry>
            <cylinder>
              <radius>0.01</radius>
              <length>0.2</length>
            </cylinder>
          </geometry>
          <material>
            <ambient>1 1 1 1</ambient>
            <diffuse>1 1 1 1</diffuse>
            <specular>0.1 0.1 0.1 1</specular>
            <emissive>0 0 0 0</emissive>
          </material>
        </visual>
        <sensor name='contact_sensor_1' type='contact'>
          <plugin name='my_contact_plugin' filename='libgazebo_ros_bumper.so'>
            <bumperTopicName>bomb_bumper</bumperTopicName>
            <frameName>world</frameName>
          </plugin>
          <contact>
            <collision>box_collision</collision>
            <topic>__default_topic__</topic>
          </contact>
        </sensor>
        <self_collide>0</self_collide>
        <inertial>
          <inertia>
            <ixx>1</ixx>
            <ixy>0</ixy>
            <ixz>0</ixz>
            <iyy>1</iyy>
            <iyz>0</iyz>
            <izz>1</izz>
          </inertia>
          <mass>1</mass>
        </inertial>
        <kinematic>0</kinematic>
      </link>
      <joint name='bomb_hinge' type='revolute'>
        <pose frame=''>0 0 0.2 0 -0 0</pose>
        <child>chassis</child>
        <parent>world</parent>
        <axis>
          <xyz>0 0 0</xyz>
          <use_parent_model_frame>1</use_parent_model_frame>
          <limit>
            <lower>-1e+16</lower>
            <upper>1e+16</upper>
          </limit>
          <dynamics>
            <spring_reference>0</spring_reference>
            <spring_stiffness>0</spring_stiffness>
          </dynamics>
        </axis>
      </joint>
      <pose frame=''>0.012015 7.3203 0 0 -0 0</pose>
    </model>
    <model name='bomb_4'>
      <link name='chassis'>
        <pose frame=''>0 0 0.25 0 -0 0</pose>
        <collision name='box_collision'>
          <geometry>
            <sphere>
              <radius>0.25</radius>
            </sphere>
          </geometry>
          <surface>
            <contact>
              <collide_bitmask>1</collide_bitmask>
              <ode>
                <min_depth>10</min_depth>
                <kp>1</kp>
              </ode>
            </contact>
            <bounce/>
            <friction>
              <torsional>
                <ode/>
              </torsional>
              <ode/>
            </friction>
          </surface>
          <max_contacts>10</max_contacts>
        </collision>
        <visual name='visual'>
          <pose frame=''>0 0 0.2 0 -0 0</pose>
          <geometry>
            <cylinder>
              <radius>0.1</radius>
              <length>0.2</length>
            </cylinder>
          </geometry>
          <material>
            <ambient>0 0 0 1</ambient>
            <diffuse>0 0 0 1</diffuse>
            <specular>0.1 0.1 0.1 1</specular>
            <emissive>0 0 0 0</emissive>
          </material>
        </visual>
        <visual name='visual2'>
          <geometry>
            <sphere>
              <radius>0.25</radius>
            </sphere>
          </geometry>
          <material>
            <ambient>0 0 0 1</ambient>
            <diffuse>0 0 0 1</diffuse>
            <specular>0.1 0.1 0.1 1</specular>
            <emissive>0 0 0 0</emissive>
          </material>
        </visual>
        <visual name='visual3'>
          <pose frame=''>0 0 0.3 0 -0 0</pose>
          <geometry>
            <cylinder>
              <radius>0.01</radius>
              <length>0.2</length>
            </cylinder>
          </geometry>
          <material>
            <ambient>1 1 1 1</ambient>
            <diffuse>1 1 1 1</diffuse>
            <specular>0.1 0.1 0.1 1</specular>
            <emissive>0 0 0 0</emissive>
          </material>
        </visual>
        <sensor name='contact_sensor_1' type='contact'>
          <plugin name='my_contact_plugin' filename='libgazebo_ros_bumper.so'>
            <bumperTopicName>bomb_bumper</bumperTopicName>
            <frameName>world</frameName>
          </plugin>
          <contact>
            <collision>box_collision</collision>
            <topic>__default_topic__</topic>
          </contact>
        </sensor>
        <self_collide>0</self_collide>
        <inertial>
          <inertia>
            <ixx>1</ixx>
            <ixy>0</ixy>
            <ixz>0</ixz>
            <iyy>1</iyy>
            <iyz>0</iyz>
            <izz>1</izz>
          </inertia>
          <mass>1</mass>
        </inertial>
        <kinematic>0</kinematic>
      </link>
      <joint name='bomb_hinge' type='revolute'>
        <pose frame=''>0 0 0.2 0 -0 0</pose>
        <child>chassis</child>
        <parent>world</parent>
        <axis>
          <xyz>0 0 0</xyz>
          <use_parent_model_frame>1</use_parent_model_frame>
          <limit>
            <lower>-1e+16</lower>
            <upper>1e+16</upper>
          </limit>
          <dynamics>
            <spring_reference>0</spring_reference>
            <spring_stiffness>0</spring_stiffness>
          </dynamics>
        </axis>
      </joint>
      <pose frame=''>5.61305 7.92236 0 0 -0 0</pose>
    </model>
    <model name='wall_1_0'>
      <static>1</static>
      <link name='chassis'>
        <pose frame=''>0 0 0.5 0 -0 0</pose>
        <collision name='barrier_collision'>
          <geometry>
            <box>
              <size>1 0.05 1</size>
            </box>
          </geometry>
          <max_contacts>10</max_contacts>
          <surface>
            <contact>
              <ode/>
            </contact>
            <bounce/>
            <friction>
              <torsional>
                <ode/>
              </torsional>
              <ode/>
            </friction>
          </surface>
        </collision>
        <visual name='visual'>
          <geometry>
            <box>
              <size>1 0.05 1</size>
            </box>
          </geometry>
          <material>
            <ambient>0.1 0.1 0.1 1</ambient>
            <diffuse>0.1 0.1 0.1 1</diffuse>
            <specular>0.1 0.1 0.1 1</specular>
            <emissive>0 0 0 0</emissive>
          </material>
        </visual>
        <sensor name='contact_sensor_1' type='contact'>
          <plugin name='my_contact_plugin' filename='libgazebo_ros_bumper.so'>
            <bumperTopicName>obstacle_bumper</bumperTopicName>
            <frameName>world</frameName>
          </plugin>
          <contact>
            <collision>barrier_collision</collision>
            <topic>__default_topic__</topic>
          </contact>
        </sensor>
        <self_collide>0</self_collide>
        <kinematic>0</kinematic>
      </link>
      <pose frame=''>7.82204 -5.25957 0 0 -0 2.67259</pose>
    </model>
    <model name='wall_1_1'>
      <static>1</static>
      <link name='chassis'>
        <pose frame=''>0 0 0.5 0 -0 0</pose>
        <collision name='barrier_collision'>
          <geometry>
            <box>
              <size>1 0.05 1</size>
            </box>
          </geometry>
          <max_contacts>10</max_contacts>
          <surface>
            <contact>
              <ode/>
            </contact>
            <bounce/>
            <friction>
              <torsional>
                <ode/>
              </torsional>
              <ode/>
            </friction>
          </surface>
        </collision>
        <visual name='visual'>
          <geometry>
            <box>
              <size>1 0.05 1</size>
            </box>
          </geometry>
          <material>
            <ambient>0.1 0.1 0.1 1</ambient>
            <diffuse>0.1 0.1 0.1 1</diffuse>
            <specular>0.1 0.1 0.1 1</specular>
            <emissive>0 0 0 0</emissive>
          </material>
        </visual>
        <sensor name='contact_sensor_1' type='contact'>
          <plugin name='my_contact_plugin' filename='libgazebo_ros_bumper.so'>
            <bumperTopicName>obstacle_bumper</bumperTopicName>
            <frameName>world</frameName>
          </plugin>
          <contact>
            <collision>barrier_collision</collision>
            <topic>__default_topic__</topic>
          </contact>
        </sensor>
        <self_collide>0</self_collide>
        <kinematic>0</kinematic>
      </link>
      <pose frame=''>1.3903 -1.2272 0 0 -0 2.05311</pose>
    </model>
    <model name='wall_1_2'>
      <static>1</static>
      <link name='chassis'>
        <pose frame=''>0 0 0.5 0 -0 0</pose>
        <collision name='barrier_collision'>
          <geometry>
            <box>
              <size>1 0.05 1</size>
            </box>
          </geometry>
          <max_contacts>10</max_contacts>
          <surface>
            <contact>
              <ode/>
            </contact>
            <bounce/>
            <friction>
              <torsional>
                <ode/>
              </torsional>
              <ode/>
            </friction>
          </surface>
        </collision>
        <visual name='visual'>
          <geometry>
            <box>
              <size>1 0.05 1</size>
            </box>
          </geometry>
          <material>
            <ambient>0.1 0.1 0.1 1</ambient>
            <diffuse>0.1 0.1 0.1 1</diffuse>
            <specular>0.1 0.1 0.1 1</specular>
            <emissive>0 0 0 0</emissive>
          </material>
        </visual>
        <sensor name='contact_sensor_1' type='contact'>
          <plugin name='my_contact_plugin' filename='libgazebo_ros_bumper.so'>
            <bumperTopicName>obstacle_bumper</bumperTopicName>
            <frameName>world</frameName>
          </plugin>
          <contact>
            <collision>barrier_collision</collision>
            <topic>__default_topic__</topic>
          </contact>
        </sensor>
        <self_collide>0</self_collide>
        <kinematic>0</kinematic>
      </link>
      <pose frame=''>-3.13099 -6.07933 0 0 0 -0.460154</pose>
    </model>
    <model name='wall_2_0'>
      <static>1</static>
      <link name='chassis'>
        <pose frame=''>0 0 0.5 0 -0 0</pose>
        <collision name='barrier_collision'>
          <geometry>
            <box>
              <size>1 0.05 1</size>
            </box>
          </geometry>
          <max_contacts>10</max_contacts>
          <surface>
            <contact>
              <ode/>
            </contact>
            <bounce/>
            <friction>
              <torsional>
                <ode/>
              </torsional>
              <ode/>
            </friction>
          </surface>
        </collision>
        <visual name='visual'>
          <geometry>
            <box>
              <size>1 0.05 1</size>
            </box>
          </geometry>
          <material>
            <ambient>0.1 0.1 0.1 1</ambient>
            <diffuse>0.1 0.1 0.1 1</diffuse>
            <specular>0.1 0.1 0.1 1</specular>
            <emissive>0 0 0 0</emissive>
          </material>
        </visual>
        <collision name='barrier_collision2'>
          <pose frame=''>-0.475 0.525 0 0 -0 1.57</pose>
          <geometry>
            <box>
              <size>1 0.05 1</size>
            </box>
          </geometry>
          <max_contacts>10</max_contacts>
          <surface>
            <contact>
              <ode/>
            </contact>
            <bounce/>
            <friction>
              <torsional>
                <ode/>
              </torsional>
              <ode/>
            </friction>
          </surface>
        </collision>
        <visual name='visual2'>
          <pose frame=''>-0.475 0.525 0 0 -0 1.57</pose>
          <geometry>
            <box>
              <size>1 0.05 1</size>
            </box>
          </geometry>
          <material>
            <ambient>0.1 0.1 0.1 1</ambient>
            <diffuse>0.1 0.1 0.1 1</diffuse>
            <specular>0.1 0.1 0.1 1</specular>
            <emissive>0 0 0 0</emissive>
          </material>
        </visual>
        <sensor name='contact_sensor_1' type='contact'>
          <plugin name='my_contact_plugin' filename='libgazebo_ros_bumper.so'>
            <bumperTopicName>obstacle_bumper</bumperTopicName>
            <frameName>world</frameName>
          </plugin>
          <contact>
            <collision>barrier_collision</collision>
            <topic>__default_topic__</topic>
          </contact>
        </sensor>
        <sensor name='contact_sensor_2' type='contact'>
          <plugin name='my_contact_plugin' filename='libgazebo_ros_bumper.so'>
            <bumperTopicName>obstacle_bumper</bumperTopicName>
            <frameName>world</frameName>
          </plugin>
          <contact>
            <collision>barrier_collision2</collision>
            <topic>__default_topic__</topic>
          </contact>
        </sensor>
        <self_collide>0</self_collide>
        <kinematic>0</kinematic>
      </link>
      <pose frame=''>-0.614454 -5.61156 0 0 -0 0.955773</pose>
    </model>
    <model name='wall_3_0'>
      <static>1</static>
      <link name='chassis'>
        <pose frame=''>0 0 0.5 0 -0 0</pose>
        <collision name='collision'>
          <geometry>
            <box>
              <size>1 0.05 1</size>
            </box>
          </geometry>
          <max_contacts>10</max_contacts>
          <surface>
            <contact>
              <ode/>
            </contact>
            <bounce/>
            <friction>
              <torsional>
                <ode/>
              </torsional>
              <ode/>
            </friction>
          </surface>
        </collision>
        <visual name='visual'>
          <geometry>
            <box>
              <size>1 0.05 1</size>
            </box>
          </geometry>
          <material>
            <ambient>0.1 0.1 0.1 1</ambient>
            <diffuse>0.1 0.1 0.1 1</diffuse>
            <specular>0.1 0.1 0.1 1</specular>
            <emissive>0 0 0 0</emissive>
          </material>
        </visual>
        <collision name='collision2'>
          <pose frame=''>-0.475 0.525 0 0 -0 1.57</pose>
          <geometry>
            <box>
              <size>1 0.05 1</size>
            </box>
          </geometry>
          <max_contacts>10</max_contacts>
          <surface>
            <contact>
              <ode/>
            </contact>
            <bounce/>
            <friction>
              <torsional>
                <ode/>
              </torsional>
              <ode/>
            </friction>
          </surface>
        </collision>
        <visual name='visual2'>
          <pose frame=''>-0.475 0.525 0 0 -0 1.57</pose>
          <geometry>
            <box>
              <size>1 0.05 1</size>
            </box>
          </geometry>
          <material>
            <ambient>0.1 0.1 0.1 1</ambient>
            <diffuse>0.1 0.1 0.1 1</diffuse>
            <specular>0.1 0.1 0.1 1</specular>
            <emissive>0 0 0 0</emissive>
          </material>
        </visual>
        <collision name='collision3'>
          <pose frame=''>0 1 0 0 -0 0</pose>
          <geometry>
            <box>
              <size>1 0.05 1</size>
            </box>
          </geometry>
          <max_contacts>10</max_contacts>
          <surface>
            <contact>
              <ode/>
            </contact>
            <bounce/>
            <friction>
              <torsional>
                <ode/>
              </torsional>
              <ode/>
            </friction>
          </surface>
        </collision>
        <visual name='visual3'>
          <pose frame=''>0 1 0 0 -0 0</pose>
          <geometry>
            <box>
              <size>1 0.05 1</size>
            </box>
          </geometry>
          <material>
            <ambient>0.1 0.1 0.1 1</ambient>
            <diffuse>0.1 0.1 0.1 1</diffuse>
            <specular>0.1 0.1 0.1 1</specular>
            <emissive>0 0 0 0</emissive>
          </material>
        </visual>
        <sensor name='contact_sensor_1' type='contact'>
          <plugin name='my_contact_plugin' filename='libgazebo_ros_bumper.so'>
            <bumperTopicName>obstacle_bumper</bumperTopicName>
            <frameName>world</frameName>
          </plugin>
          <contact>
            <collision>collision</collision>
            <topic>__default_topic__</topic>
          </contact>
        </sensor>
        <sensor name='contact_sensor_2' type='contact'>
          <plugin name='my_contact_plugin' filename='libgazebo_ros_bumper.so'>
            <bumperTopicName>obstacle_bumper</bumperTopicName>
            <frameName>world</frameName>
          </plugin>
          <contact>
            <collision>collision2</collision>
            <topic>__default_topic__</topic>
          </contact>
        </sensor>
        <sensor name='contact_sensor_3' type='contact'>
          <plugin name='my_contact_plugin' filename='libgazebo_ros_bumper.so'>
            <bumperTopicName>obstacle_bumper</bumperTopicName>
            <frameName>world</frameName>
          </plugin>
          <contact>
            <collision>collision3</collision>
            <topic>__default_topic__</topic>
          </contact>
        </sensor>
        <self_collide>0</self_collide>
        <kinematic>0</kinematic>
      </link>
      <pose frame=''>-2.28394 -1.55685 0 0 -0 0.238958</pose>
    </model>
    <model name='wall_1_3'>
      <static>1</static>
      <link name='chassis'>
        <pose frame=''>0 0 0.5 0 -0 0</pose>
        <collision name='barrier_collision'>
          <geometry>
            <box>
              <size>1 0.05 1</size>
            </box>
          </geometry>
          <max_contacts>10</max_contacts>
          <surface>
            <contact>
              <ode/>
            </contact>
            <bounce/>
            <friction>
              <torsional>
                <ode/>
              </torsional>
              <ode/>
            </friction>
          </surface>
        </collision>
        <visual name='visual'>
          <geometry>
            <box>
              <size>1 0.05 1</size>
            </box>
          </geometry>
          <material>
            <ambient>0.1 0.1 0.1 1</ambient>
            <diffuse>0.1 0.1 0.1 1</diffuse>
            <specular>0.1 0.1 0.1 1</specular>
            <emissive>0 0 0 0</emissive>
          </material>
        </visual>
        <sensor name='contact_sensor_1' type='contact'>
          <plugin name='my_contact_plugin' filename='libgazebo_ros_bumper.so'>
            <bumperTopicName>obstacle_bumper</bumperTopicName>
            <frameName>world</frameName>
          </plugin>
          <contact>
            <collision>barrier_collision</collision>
            <topic>__default_topic__</topic>
          </contact>
        </sensor>
        <self_collide>0</self_collide>
        <kinematic>0</kinematic>
      </link>
      <pose frame=''>-2.57759 1.72433 0 0 -0 0.070811</pose>
    </model>
    <model name='wall_2_1'>
      <static>1</static>
      <link name='chassis'>
        <pose frame=''>0 0 0.5 0 -0 0</pose>
        <collision name='barrier_collision'>
          <geometry>
            <box>
              <size>1 0.05 1</size>
            </box>
          </geometry>
          <max_contacts>10</max_contacts>
          <surface>
            <contact>
              <ode/>
            </contact>
            <bounce/>
            <friction>
              <torsional>
                <ode/>
              </torsional>
              <ode/>
            </friction>
          </surface>
        </collision>
        <visual name='visual'>
          <geometry>
            <box>
              <size>1 0.05 1</size>
            </box>
          </geometry>
          <material>
            <ambient>0.1 0.1 0.1 1</ambient>
            <diffuse>0.1 0.1 0.1 1</diffuse>
            <specular>0.1 0.1 0.1 1</specular>
            <emissive>0 0 0 0</emissive>
          </material>
        </visual>
        <collision name='barrier_collision2'>
          <pose frame=''>-0.475 0.525 0 0 -0 1.57</pose>
          <geometry>
            <box>
              <size>1 0.05 1</size>
            </box>
          </geometry>
          <max_contacts>10</max_contacts>
          <surface>
            <contact>
              <ode/>
            </contact>
            <bounce/>
            <friction>
              <torsional>
                <ode/>
              </torsional>
              <ode/>
            </friction>
          </surface>
        </collision>
        <visual name='visual2'>
          <pose frame=''>-0.475 0.525 0 0 -0 1.57</pose>
          <geometry>
            <box>
              <size>1 0.05 1</size>
            </box>
          </geometry>
          <material>
            <ambient>0.1 0.1 0.1 1</ambient>
            <diffuse>0.1 0.1 0.1 1</diffuse>
            <specular>0.1 0.1 0.1 1</specular>
            <emissive>0 0 0 0</emissive>
          </material>
        </visual>
        <sensor name='contact_sensor_1' type='contact'>
          <plugin name='my_contact_plugin' filename='libgazebo_ros_bumper.so'>
            <bumperTopicName>obstacle_bumper</bumperTopicName>
            <frameName>world</frameName>
          </plugin>
          <contact>
            <collision>barrier_collision</collision>
            <topic>__default_topic__</topic>
          </contact>
        </sensor>
        <sensor name='contact_sensor_2' type='contact'>
          <plugin name='my_contact_plugin' filename='libgazebo_ros_bumper.so'>
            <bumperTopicName>obstacle_bumper</bumperTopicName>
            <frameName>world</frameName>
          </plugin>
          <contact>
            <collision>barrier_collision2</collision>
            <topic>__default_topic__</topic>
          </contact>
        </sensor>
        <self_collide>0</self_collide>
        <kinematic>0</kinematic>
      </link>
      <pose frame=''>-3.98629 4.69015 0 0 -0 3.07081</pose>
    </model>
    <model name='wall_3_1'>
      <static>1</static>
      <link name='chassis'>
        <pose frame=''>0 0 0.5 0 -0 0</pose>
        <collision name='collision'>
          <geometry>
            <box>
              <size>1 0.05 1</size>
            </box>
          </geometry>
          <max_contacts>10</max_contacts>
          <surface>
            <contact>
              <ode/>
            </contact>
            <bounce/>
            <friction>
              <torsional>
                <ode/>
              </torsional>
              <ode/>
            </friction>
          </surface>
        </collision>
        <visual name='visual'>
          <geometry>
            <box>
              <size>1 0.05 1</size>
            </box>
          </geometry>
          <material>
            <ambient>0.1 0.1 0.1 1</ambient>
            <diffuse>0.1 0.1 0.1 1</diffuse>
            <specular>0.1 0.1 0.1 1</specular>
            <emissive>0 0 0 0</emissive>
          </material>
        </visual>
        <collision name='collision2'>
          <pose frame=''>-0.475 0.525 0 0 -0 1.57</pose>
          <geometry>
            <box>
              <size>1 0.05 1</size>
            </box>
          </geometry>
          <max_contacts>10</max_contacts>
          <surface>
            <contact>
              <ode/>
            </contact>
            <bounce/>
            <friction>
              <torsional>
                <ode/>
              </torsional>
              <ode/>
            </friction>
          </surface>
        </collision>
        <visual name='visual2'>
          <pose frame=''>-0.475 0.525 0 0 -0 1.57</pose>
          <geometry>
            <box>
              <size>1 0.05 1</size>
            </box>
          </geometry>
          <material>
            <ambient>0.1 0.1 0.1 1</ambient>
            <diffuse>0.1 0.1 0.1 1</diffuse>
            <specular>0.1 0.1 0.1 1</specular>
            <emissive>0 0 0 0</emissive>
          </material>
        </visual>
        <collision name='collision3'>
          <pose frame=''>0 1 0 0 -0 0</pose>
          <geometry>
            <box>
              <size>1 0.05 1</size>
            </box>
          </geometry>
          <max_contacts>10</max_contacts>
          <surface>
            <contact>
              <ode/>
            </contact>
            <bounce/>
            <friction>
              <torsional>
                <ode/>
              </torsional>
              <ode/>
            </friction>
          </surface>
        </collision>
        <visual name='visual3'>
          <pose frame=''>0 1 0 0 -0 0</pose>
          <geometry>
            <box>
              <size>1 0.05 1</size>
            </box>
          </geometry>
          <material>
            <ambient>0.1 0.1 0.1 1</ambient>
            <diffuse>0.1 0.1 0.1 1</diffuse>
            <specular>0.1 0.1 0.1 1</specular>
            <emissive>0 0 0 0</emissive>
          </material>
        </visual>
        <sensor name='contact_sensor_1' type='contact'>
          <plugin name='my_contact_plugin' filename='libgazebo_ros_bumper.so'>
            <bumperTopicName>obstacle_bumper</bumperTopicName>
            <frameName>world</frameName>
          </plugin>
          <contact>
            <collision>collision</collision>
            <topic>__default_topic__</topic>
          </contact>
        </sensor>
        <sensor name='contact_sensor_2' type='contact'>
          <plugin name='my_contact_plugin' filename='libgazebo_ros_bumper.so'>
            <bumperTopicName>obstacle_bumper</bumperTopicName>
            <frameName>world</frameName>
          </plugin>
          <contact>
            <collision>collision2</collision>
            <topic>__default_topic__</topic>
          </contact>
        </sensor>
        <sensor name='contact_sensor_3' type='contact'>
          <plugin name='my_contact_plugin' filename='libgazebo_ros_bumper.so'>
            <bumperTopicName>obstacle_bumper</bumperTopicName>
            <frameName>world</frameName>
          </plugin>
          <contact>
            <collision>collision3</collision>
            <topic>__default_topic__</topic>
          </contact>
        </sensor>
        <self_collide>0</self_collide>
        <kinematic>0</kinematic>
      </link>
      <pose frame=''>-4.257 6.98275 0 0 -0 2.25666</pose>
    </model>
    <model name='wall_1_4'>
      <static>1</static>
      <link name='chassis'>
        <pose frame=''>0 0 0.5 0 -0 0</pose>
        <collision name='barrier_collision'>
          <geometry>
            <box>
              <size>1 0.05 1</size>
            </box>
          </geometry>
          <max_contacts>10</max_contacts>
          <surface>
            <contact>
              <ode/>
            </contact>
            <bounce/>
            <friction>
              <torsional>
                <ode/>
              </torsional>
              <ode/>
            </friction>
          </surface>
        </collision>
        <visual name='visual'>
          <geometry>
            <box>
              <size>1 0.05 1</size>
            </box>
          </geometry>
          <material>
            <ambient>0.1 0.1 0.1 1</ambient>
            <diffuse>0.1 0.1 0.1 1</diffuse>
            <specular>0.1 0.1 0.1 1</specular>
            <emissive>0 0 0 0</emissive>
          </material>
        </visual>
        <sensor name='contact_sensor_1' type='contact'>
          <plugin name='my_contact_plugin' filename='libgazebo_ros_bumper.so'>
            <bumperTopicName>obstacle_bumper</bumperTopicName>
            <frameName>world</frameName>
          </plugin>
          <contact>
            <collision>barrier_collision</collision>
            <topic>__default_topic__</topic>
          </contact>
        </sensor>
        <self_collide>0</self_collide>
        <kinematic>0</kinematic>
      </link>
      <pose frame=''>5.23467 6.34425 0 0 -0 2.93807</pose>
    </model>
    <model name='wall_2_2'>
      <static>1</static>
      <link name='chassis'>
        <pose frame=''>0 0 0.5 0 -0 0</pose>
        <collision name='barrier_collision'>
          <geometry>
            <box>
              <size>1 0.05 1</size>
            </box>
          </geometry>
          <max_contacts>10</max_contacts>
          <surface>
            <contact>
              <ode/>
            </contact>
            <bounce/>
            <friction>
              <torsional>
                <ode/>
              </torsional>
              <ode/>
            </friction>
          </surface>
        </collision>
        <visual name='visual'>
          <geometry>
            <box>
              <size>1 0.05 1</size>
            </box>
          </geometry>
          <material>
            <ambient>0.1 0.1 0.1 1</ambient>
            <diffuse>0.1 0.1 0.1 1</diffuse>
            <specular>0.1 0.1 0.1 1</specular>
            <emissive>0 0 0 0</emissive>
          </material>
        </visual>
        <collision name='barrier_collision2'>
          <pose frame=''>-0.475 0.525 0 0 -0 1.57</pose>
          <geometry>
            <box>
              <size>1 0.05 1</size>
            </box>
          </geometry>
          <max_contacts>10</max_contacts>
          <surface>
            <contact>
              <ode/>
            </contact>
            <bounce/>
            <friction>
              <torsional>
                <ode/>
              </torsional>
              <ode/>
            </friction>
          </surface>
        </collision>
        <visual name='visual2'>
          <pose frame=''>-0.475 0.525 0 0 -0 1.57</pose>
          <geometry>
            <box>
              <size>1 0.05 1</size>
            </box>
          </geometry>
          <material>
            <ambient>0.1 0.1 0.1 1</ambient>
            <diffuse>0.1 0.1 0.1 1</diffuse>
            <specular>0.1 0.1 0.1 1</specular>
            <emissive>0 0 0 0</emissive>
          </material>
        </visual>
        <sensor name='contact_sensor_1' type='contact'>
          <plugin name='my_contact_plugin' filename='libgazebo_ros_bumper.so'>
            <bumperTopicName>obstacle_bumper</bumperTopicName>
            <frameName>world</frameName>
          </plugin>
          <contact>
            <collision>barrier_collision</collision>
            <topic>__default_topic__</topic>
          </contact>
        </sensor>
        <sensor name='contact_sensor_2' type='contact'>
          <plugin name='my_contact_plugin' filename='libgazebo_ros_bumper.so'>
            <bumperTopicName>obstacle_bumper</bumperTopicName>
            <frameName>world</frameName>
          </plugin>
          <contact>
            <collision>barrier_collision2</collision>
            <topic>__default_topic__</topic>
          </contact>
        </sensor>
        <self_collide>0</self_collide>
        <kinematic>0</kinematic>
      </link>
      <pose frame=''>5.2617 4.66455 0 0 0 -0.442451</pose>
    </model>
    <model name='obj_1'>
      <static>1</static>
      <link name='chassis'>
        <pose frame=''>0 0 0.5 -1.5708 0 0</pose>
        <collision name='collision'>
          <geometry>
            <mesh>
              <uri>model://airplane_green/meshes/plane_fixed.dae</uri>
            </mesh>
          </geometry>
          <max_contacts>10</max_contacts>
          <surface>
            <contact>
              <ode/>
            </contact>
            <bounce/>
            <friction>
              <torsional>
                <ode/>
              </torsional>
              <ode/>
            </friction>
          </surface>
        </collision>
        <visual name='visual'>
          <pose frame=''>0 0 0 0 -0 0</pose>
          <geometry>
            <mesh>
              <uri>model://airplane_green/meshes/plane_fixed.dae</uri>
            </mesh>
          </geometry>
          <material>
            <ambient>0 1 0 1</ambient>
            <diffuse>0 1 0 1</diffuse>
            <specular>0.1 0.1 0.1 1</specular>
            <emissive>0 0 0 0</emissive>
          </material>
        </visual>
        <self_collide>0</self_collide>
        <kinematic>0</kinematic>
      </link>
      <pose frame=''>1.87372 -6.60046 0 0 0 -0.442451</pose>
    </model>
    <model name='obj_2'>
      <static>1</static>
      <link name='chassis'>
        <pose frame=''>0 0 0.5 -1.5708 0 0</pose>
        <collision name='collision'>
          <geometry>
            <mesh>
              <uri>model://airplane_red/meshes/plane_fixed.dae</uri>
            </mesh>
          </geometry>
          <max_contacts>10</max_contacts>
          <surface>
            <contact>
              <ode/>
            </contact>
            <bounce/>
            <friction>
              <torsional>
                <ode/>
              </torsional>
              <ode/>
            </friction>
          </surface>
        </collision>
        <visual name='visual'>
          <pose frame=''>0 0 0 0 -0 0</pose>
          <geometry>
            <mesh>
              <uri>model://airplane_red/meshes/plane_fixed.dae</uri>
            </mesh>
          </geometry>
          <material>
            <ambient>1 0 0 1</ambient>
            <diffuse>1 0 0 1</diffuse>
            <specular>0.1 0.1 0.1 1</specular>
            <emissive>0 0 0 0</emissive>
          </material>
        </visual>
        <self_collide>0</self_collide>
        <kinematic>0</kinematic>
      </link>
      <pose frame=''>5.35861 -7.35348 0 0 0 -0.442451</pose>
    </model>
    <model name='obj_4'>
      <static>1</static>
      <link name='chassis'>
        <pose frame=''>0 0 0.5 -1.5708 0 0</pose>
        <collision name='collision'>
          <geometry>
            <mesh>
              <uri>model://bike_green/meshes/bike.dae</uri>
            </mesh>
          </geometry>
          <max_contacts>10</max_contacts>
          <surface>
            <contact>
              <ode/>
            </contact>
            <bounce/>
            <friction>
              <torsional>
                <ode/>
              </torsional>
              <ode/>
            </friction>
          </surface>
        </collision>
        <visual name='visual'>
          <pose frame=''>0 0 0 0 -0 0</pose>
          <geometry>
            <mesh>
              <uri>model://bike_green/meshes/bike.dae</uri>
            </mesh>
          </geometry>
          <material>
            <ambient>0 1 0 1</ambient>
            <diffuse>0 1 0 1</diffuse>
            <specular>0.1 0.1 0.1 1</specular>
            <emissive>0 0 0 0</emissive>
          </material>
        </visual>
        <self_collide>0</self_collide>
        <kinematic>0</kinematic>
      </link>
      <pose frame=''>-5.35199 -6.11553 0 0 0 -0.442451</pose>
    </model>
    <model name='obj_5'>
      <static>1</static>
      <link name='chassis'>
        <pose frame=''>0 0 0.5 -1.5708 0 0</pose>
        <collision name='collision'>
          <geometry>
            <mesh>
              <uri>model://bike_red/meshes/bike.dae</uri>
            </mesh>
          </geometry>
          <max_contacts>10</max_contacts>
          <surface>
            <contact>
              <ode/>
            </contact>
            <bounce/>
            <friction>
              <torsional>
                <ode/>
              </torsional>
              <ode/>
            </friction>
          </surface>
        </collision>
        <visual name='visual'>
          <pose frame=''>0 0 0 0 -0 0</pose>
          <geometry>
            <mesh>
              <uri>model://bike_red/meshes/bike.dae</uri>
            </mesh>
          </geometry>
          <material>
            <ambient>1 0 0 1</ambient>
            <diffuse>1 0 0 1</diffuse>
            <specular>0.1 0.1 0.1 1</specular>
            <emissive>0 0 0 0</emissive>
          </material>
        </visual>
        <self_collide>0</self_collide>
        <kinematic>0</kinematic>
      </link>
      <pose frame=''>-6.717 -1.96356 0 0 0 -0.442451</pose>
    </model>
    <model name='obj_6'>
      <static>1</static>
      <link name='chassis'>
        <pose frame=''>0 0 0.5 -1.5708 0 0</pose>
        <collision name='collision'>
          <geometry>
            <mesh>
              <uri>model://boat_blue/meshes/boat_fixed.dae</uri>
            </mesh>
          </geometry>
          <max_contacts>10</max_contacts>
          <surface>
            <contact>
              <ode/>
            </contact>
            <bounce/>
            <friction>
              <torsional>
                <ode/>
              </torsional>
              <ode/>
            </friction>
          </surface>
        </collision>
        <visual name='visual'>
          <pose frame=''>0 0 0 0 -0 0</pose>
          <geometry>
            <mesh>
              <uri>model://boat_blue/meshes/boat_fixed.dae</uri>
            </mesh>
          </geometry>
          <material>
            <ambient>0 0 1 1</ambient>
            <diffuse>0 0 1 1</diffuse>
            <specular>0.1 0.1 0.1 1</specular>
            <emissive>0 0 0 0</emissive>
          </material>
        </visual>
        <self_collide>0</self_collide>
        <kinematic>0</kinematic>
      </link>
      <pose frame=''>-8.92688 8.99905 0 0 0 -0.442451</pose>
    </model>
    <model name='obj_7'>
      <static>1</static>
      <link name='chassis'>
        <pose frame=''>0 0 0.5 -1.5708 0 0</pose>
        <collision name='collision'>
          <geometry>
            <mesh>
              <uri>model://boat_green/meshes/boat_fixed.dae</uri>
            </mesh>
          </geometry>
          <max_contacts>10</max_contacts>
          <surface>
            <contact>
              <ode/>
            </contact>
            <bounce/>
            <friction>
              <torsional>
                <ode/>
              </torsional>
              <ode/>
            </friction>
          </surface>
        </collision>
        <visual name='visual'>
          <pose frame=''>0 0 0 0 -0 0</pose>
          <geometry>
            <mesh>
              <uri>model://boat_green/meshes/boat_fixed.dae</uri>
            </mesh>
          </geometry>
          <material>
            <ambient>0 1 0 1</ambient>
            <diffuse>0 1 0 1</diffuse>
            <specular>0.1 0.1 0.1 1</specular>
            <emissive>0 0 0 0</emissive>
          </material>
        </visual>
        <self_collide>0</self_collide>
        <kinematic>0</kinematic>
      </link>
      <pose frame=''>-3.52041 6.083 0 0 0 -0.442451</pose>
    </model>
    <model name='obj_8'>
      <static>1</static>
      <link name='chassis'>
        <pose frame=''>0 0 0.5 -1.5708 0 0</pose>
        <collision name='collision'>
          <geometry>
            <mesh>
              <uri>model://boat_red/meshes/boat_fixed.dae</uri>
            </mesh>
          </geometry>
          <max_contacts>10</max_contacts>
          <surface>
            <contact>
              <ode/>
            </contact>
            <bounce/>
            <friction>
              <torsional>
                <ode/>
              </torsional>
              <ode/>
            </friction>
          </surface>
        </collision>
        <visual name='visual'>
          <pose frame=''>0 0 0 0 -0 0</pose>
          <geometry>
            <mesh>
              <uri>model://boat_red/meshes/boat_fixed.dae</uri>
            </mesh>
          </geometry>
          <material>
            <ambient>1 0 0 1</ambient>
            <diffuse>1 0 0 1</diffuse>
            <specular>0.1 0.1 0.1 1</specular>
            <emissive>0 0 0 0</emissive>
          </material>
        </visual>
        <self_collide>0</self_collide>
        <kinematic>0</kinematic>
      </link>
      <pose frame=''>-2.57853 7.20392 0 0 0 -0.442451</pose>
    </model>
    <model name='obj_9'>
      <static>1</static>
      <link name='chassis'>
        <pose frame=''>0 0 0.5 -1.5708 0 0</pose>
        <collision name='collision'>
          <geometry>
            <mesh>
              <uri>model://bottle_blue/meshes/bottle.dae</uri>
            </mesh>
          </geometry>
          <max_contacts>10</max_contacts>
          <surface>
            <contact>
              <ode/>
            </contact>
            <bounce/>
            <friction>
              <torsional>
                <ode/>
              </torsional>
              <ode/>
            </friction>
          </surface>
        </collision>
        <visual name='visual'>
          <pose frame=''>0 0 0 0 -0 0</pose>
          <geometry>
            <mesh>
              <uri>model://bottle_blue/meshes/bottle.dae</uri>
            </mesh>
          </geometry>
          <material>
            <ambient>0 0 1 1</ambient>
            <diffuse>0 0 1 1</diffuse>
            <specular>0.1 0.1 0.1 1</specular>
            <emissive>0 0 0 0</emissive>
          </material>
        </visual>
        <self_collide>0</self_collide>
        <kinematic>0</kinematic>
      </link>
      <pose frame=''>1.50359 2.43518 0 0 0 -0.442451</pose>
    </model>
    <model name='obj_10'>
      <static>1</static>
      <link name='chassis'>
        <pose frame=''>0 0 0.5 -1.5708 0 0</pose>
        <collision name='collision'>
          <geometry>
            <mesh>
              <uri>model://bottle_green/meshes/bottle.dae</uri>
            </mesh>
          </geometry>
          <max_contacts>10</max_contacts>
          <surface>
            <contact>
              <ode/>
            </contact>
            <bounce/>
            <friction>
              <torsional>
                <ode/>
              </torsional>
              <ode/>
            </friction>
          </surface>
        </collision>
        <visual name='visual'>
          <pose frame=''>0 0 0 0 -0 0</pose>
          <geometry>
            <mesh>
              <uri>model://bottle_green/meshes/bottle.dae</uri>
            </mesh>
          </geometry>
          <material>
            <ambient>0 1 0 1</ambient>
            <diffuse>0 1 0 1</diffuse>
            <specular>0.1 0.1 0.1 1</specular>
            <emissive>0 0 0 0</emissive>
          </material>
        </visual>
        <self_collide>0</self_collide>
        <kinematic>0</kinematic>
      </link>
      <pose frame=''>2.89407 6.01029 0 0 0 -0.442451</pose>
    </model>
    <model name='obj_11'>
      <static>1</static>
      <link name='chassis'>
        <pose frame=''>0 0 0.5 -1.5708 0 0</pose>
        <collision name='collision'>
          <geometry>
            <mesh>
              <uri>model://bottle_red/meshes/bottle.dae</uri>
            </mesh>
          </geometry>
          <max_contacts>10</max_contacts>
          <surface>
            <contact>
              <ode/>
            </contact>
            <bounce/>
            <friction>
              <torsional>
                <ode/>
              </torsional>
              <ode/>
            </friction>
          </surface>
        </collision>
        <visual name='visual'>
          <pose frame=''>0 0 0 0 -0 0</pose>
          <geometry>
            <mesh>
              <uri>model://bottle_red/meshes/bottle.dae</uri>
            </mesh>
          </geometry>
          <material>
            <ambient>1 0 0 1</ambient>
            <diffuse>1 0 0 1</diffuse>
            <specular>0.1 0.1 0.1 1</specular>
            <emissive>0 0 0 0</emissive>
          </material>
        </visual>
        <self_collide>0</self_collide>
        <kinematic>0</kinematic>
      </link>
      <pose frame=''>7.17818 0.876818 0 0 0 -0.442451</pose>
    </model>
    <model name='info_6'>
      <static>1</static>
      <link name='chassis'>
        <pose frame=''>0 0 0.5 0 -0 0</pose>
        <collision name='collision'>
          <geometry>
            <box>
              <size>0.5 0.5 0.5</size>
            </box>
          </geometry>
          <max_contacts>10</max_contacts>
          <surface>
            <contact>
              <ode/>
            </contact>
            <bounce/>
            <friction>
              <torsional>
                <ode/>
              </torsional>
              <ode/>
            </friction>
          </surface>
        </collision>
        <visual name='visual'>
          <geometry>
            <box>
              <size>0.5 0.5 0.5</size>
            </box>
          </geometry>
          <material>
            <script>
              <uri>model://aruco_cube/materials/scripts/aruco_6.material</uri>
              <uri>model://aruco_cube/materials/textures</uri>
              <name>Aruco6/Diffuse</name>
            </script>
          </material>
        </visual>
        <self_collide>0</self_collide>
        <kinematic>0</kinematic>
      </link>
      <pose frame=''>-8.07193 7.75841 0 0 0 -0.442451</pose>
    </model>
    <state world_name='default'>
      <sim_time>72 325000000</sim_time>
      <real_time>81 485707286</real_time>
      <wall_time>1529401026 894536967</wall_time>
      <iterations>72325</iterations>
      <model name='bomb_0'>
        <pose frame=''>8.72929 -6.70741 0 0 -0 0</pose>
        <scale>1 1 1</scale>
        <link name='chassis'>
          <pose frame=''>8.72929 -6.70741 0.25 0 -0 0</pose>
          <velocity>0 0 0 0 -0 0</velocity>
          <acceleration>0 0 0 0 -0 0</acceleration>
          <wrench>0 0 0 0 -0 0</wrench>
        </link>
      </model>
      <model name='bomb_1'>
        <pose frame=''>-6.34067 -8.50757 1e-06 0.001707 -0 0</pose>
        <scale>1 1 1</scale>
        <link name='chassis'>
          <pose frame=''>-6.34067 -8.508 0.25 0.001707 -0 0</pose>
          <velocity>0 0.000758 1e-06 0.00379 -0 0</velocity>
          <acceleration>0 -0.000642 2e-06 -0.003211 0 0</acceleration>
          <wrench>0 -0.000642 2e-06 0 -0 0</wrench>
        </link>
      </model>
      <model name='bomb_3'>
        <pose frame=''>0.012015 7.3203 0 0 -0 0</pose>
        <scale>1 1 1</scale>
        <link name='chassis'>
          <pose frame=''>0.012015 7.3203 0.25 0 -0 0</pose>
          <velocity>0 0 0 0 -0 0</velocity>
          <acceleration>0 0 0 0 -0 0</acceleration>
          <wrench>0 0 0 0 -0 0</wrench>
        </link>
      </model>
      <model name='bomb_4'>
        <pose frame=''>5.61305 7.92236 0 0 -0 0</pose>
        <scale>1 1 1</scale>
        <link name='chassis'>
          <pose frame=''>5.61305 7.92236 0.25 0 -0 0</pose>
          <velocity>0 0 0 0 -0 0</velocity>
          <acceleration>0 0 0 0 -0 0</acceleration>
          <wrench>0 0 0 0 -0 0</wrench>
        </link>
      </model>
      <model name='borders'>
        <pose frame=''>0 0 0 0 -0 0</pose>
        <scale>1 1 1</scale>
        <link name='chassis_neg_x'>
          <pose frame=''>-10 0 0.35 0 -0 1.57079</pose>
          <velocity>0 0 0 0 -0 0</velocity>
          <acceleration>0 0 0 0 -0 0</acceleration>
          <wrench>0 0 0 0 -0 0</wrench>
        </link>
        <link name='chassis_neg_y'>
          <pose frame=''>0 -10 0.35 0 -0 0</pose>
          <velocity>0 0 0 0 -0 0</velocity>
          <acceleration>0 0 0 0 -0 0</acceleration>
          <wrench>0 0 0 0 -0 0</wrench>
        </link>
        <link name='chassis_pos_x'>
          <pose frame=''>10 0 0.35 0 -0 1.57079</pose>
          <velocity>0 0 0 0 -0 0</velocity>
          <acceleration>0 0 0 0 -0 0</acceleration>
          <wrench>0 0 0 0 -0 0</wrench>
        </link>
        <link name='chassis_pos_y'>
          <pose frame=''>0 10 0.35 0 -0 0</pose>
          <velocity>0 0 0 0 -0 0</velocity>
          <acceleration>0 0 0 0 -0 0</acceleration>
          <wrench>0 0 0 0 -0 0</wrench>
        </link>
      </model>
      <model name='coin_0'>
        <pose frame=''>0.179485 -1.53193 0 0 -0 1.85607</pose>
        <scale>1 1 1</scale>
        <link name='chassis'>
          <pose frame=''>0.179485 -1.53193 0.26 0 -0 1.85607</pose>
          <velocity>0 0 0 0 0 -1.28319</velocity>
          <acceleration>0 0 0 0 -0 0</acceleration>
          <wrench>0 0 0 0 -0 0</wrench>
        </link>
      </model>
      <model name='coin_1'>
        <pose frame=''>1.76429 -4.46358 0 0 0 -0.158928</pose>
        <scale>1 1 1</scale>
        <link name='chassis'>
          <pose frame=''>1.76429 -4.46358 0.26 0 0 -0.158928</pose>
          <velocity>0 0 0 0 0 -1.28319</velocity>
          <acceleration>0 0 0 0 -0 0</acceleration>
          <wrench>0 0 0 0 -0 0</wrench>
        </link>
      </model>
      <model name='coin_2'>
        <pose frame=''>5.98475 -4.69508 0 0 0 -2.35718</pose>
        <scale>1 1 1</scale>
        <link name='chassis'>
          <pose frame=''>5.98475 -4.69508 0.26 0 0 -2.35718</pose>
          <velocity>0 0 0 0 0 -1.28663</velocity>
          <acceleration>0 0 0 0 -0 0</acceleration>
          <wrench>0 0 0 0 -0 0</wrench>
        </link>
      </model>
      <model name='coin_3'>
        <pose frame=''>-4.69873 -5.44036 0 0 -0 2.09927</pose>
        <scale>1 1 1</scale>
        <link name='chassis'>
          <pose frame=''>-4.69873 -5.44036 0.26 0 -0 2.09927</pose>
          <velocity>0 0 0 0 0 -1.28319</velocity>
          <acceleration>0 0 0 0 -0 0</acceleration>
          <wrench>0 0 0 0 -0 0</wrench>
        </link>
      </model>
      <model name='coin_6'>
        <pose frame=''>-4.94528 8.82124 0 0 -0 2.32258</pose>
        <scale>1 1 1</scale>
        <link name='chassis'>
          <pose frame=''>-4.94528 8.82124 0.26 0 -0 2.32258</pose>
          <velocity>0 0 0 0 0 -1.28319</velocity>
          <acceleration>0 0 0 0 -0 0</acceleration>
          <wrench>0 0 0 0 -0 0</wrench>
        </link>
      </model>
      <model name='coin_7'>
        <pose frame=''>-0.293643 3.28118 0 0 -0 0.317468</pose>
        <scale>1 1 1</scale>
        <link name='chassis'>
          <pose frame=''>-0.293643 3.28118 0.26 0 -0 0.317468</pose>
          <velocity>0 0 0 0 0 -1.28319</velocity>
          <acceleration>0 0 0 0 -0 0</acceleration>
          <wrench>0 0 0 0 -0 0</wrench>
        </link>
      </model>
      <model name='coin_8'>
        <pose frame=''>7.4107 7.5913 0 0 0 -1.68753</pose>
        <scale>1 1 1</scale>
        <link name='chassis'>
          <pose frame=''>7.4107 7.5913 0.26 0 0 -1.68753</pose>
          <velocity>0 0 0 0 0 -1.28319</velocity>
          <acceleration>0 0 0 0 -0 0</acceleration>
          <wrench>0 0 0 0 -0 0</wrench>
        </link>
      </model>
      <model name='coin_9'>
        <pose frame=''>2.96582 0.086113 0 0 -0 2.58066</pose>
        <scale>1 1 1</scale>
        <link name='chassis'>
          <pose frame=''>2.96582 0.086113 0.26 0 -0 2.58066</pose>
          <velocity>0 0 0 0 0 -1.28319</velocity>
          <acceleration>0 0 0 0 -0 0</acceleration>
          <wrench>0 0 0 0 -0 0</wrench>
        </link>
      </model>
      <model name='info_6'>
        <pose frame=''>-8.07193 7.75841 0 0 0 -0.442451</pose>
        <scale>1 1 1</scale>
        <link name='chassis'>
          <pose frame=''>-8.07193 7.75841 0.5 0 0 -0.442451</pose>
          <velocity>0 0 0 0 -0 0</velocity>
          <acceleration>0 0 0 0 -0 0</acceleration>
          <wrench>0 0 0 0 -0 0</wrench>
        </link>
      </model>
      <model name='labrob_ground'>
        <pose frame=''>0 0 0 0 -0 0</pose>
        <scale>1 1 1</scale>
        <link name='link'>
          <pose frame=''>0 0 0 0 -0 0</pose>
          <velocity>0 0 0 0 -0 0</velocity>
          <acceleration>0 0 0 0 -0 0</acceleration>
          <wrench>0 0 0 0 -0 0</wrench>
        </link>
      </model>
      <model name='obj_1'>
        <pose frame=''>1.87372 -6.60046 0 0 0 -0.442451</pose>
        <scale>1 1 1</scale>
        <link name='chassis'>
          <pose frame=''>1.87372 -6.60046 0.5 -1.5708 -0 -0.442451</pose>
          <velocity>0 0 0 0 -0 0</velocity>
          <acceleration>0 0 0 0 -0 0</acceleration>
          <wrench>0 0 0 0 -0 0</wrench>
        </link>
      </model>
      <model name='obj_10'>
        <pose frame=''>2.89407 6.01029 0 0 0 -0.442451</pose>
        <scale>1 1 1</scale>
        <link name='chassis'>
          <pose frame=''>2.89407 6.01029 0.5 -1.5708 -0 -0.442451</pose>
          <velocity>0 0 0 0 -0 0</velocity>
          <acceleration>0 0 0 0 -0 0</acceleration>
          <wrench>0 0 0 0 -0 0</wrench>
        </link>
      </model>
      <model name='obj_11'>
        <pose frame=''>7.17818 0.876818 0 0 0 -0.442451</pose>
        <scale>1 1 1</scale>
        <link name='chassis'>
          <pose frame=''>7.17818 0.876818 0.5 -1.5708 -0 -0.442451</pose>
          <velocity>0 0 0 0 -0 0</velocity>
          <acceleration>0 0 0 0 -0 0</acceleration>
          <wrench>0 0 0 0 -0 0</wrench>
        </link>
      </model>
      <model name='obj_2'>
        <pose frame=''>5.35861 -7.35348 0 0 0 -0.442451</pose>
        <scale>1 1 1</scale>
        <link name='chassis'>
          <pose frame=''>5.35861 -7.35348 0.5 -1.5708 -0 -0.442451</pose>
          <velocity>0 0 0 0 -0 0</velocity>
          <acceleration>0 0 0 0 -0 0</acceleration>
          <wrench>0 0 0 0 -0 0</wrench>
        </link>
      </model>
      <model name='obj_4'>
        <pose frame=''>-5.35199 -6.11553 0 0 0 -0.442451</pose>
        <scale>1 1 1</scale>
        <link name='chassis'>
          <pose frame=''>-5.35199 -6.11553 0.5 -1.5708 -0 -0.442451</pose>
          <velocity>0 0 0 0 -0 0</velocity>
          <acceleration>0 0 0 0 -0 0</acceleration>
          <wrench>0 0 0 0 -0 0</wrench>
        </link>
      </model>
      <model name='obj_5'>
        <pose frame=''>-6.717 -1.96356 0 0 0 -0.442451</pose>
        <scale>1 1 1</scale>
        <link name='chassis'>
          <pose frame=''>-6.717 -1.96356 0.5 -1.5708 -0 -0.442451</pose>
          <velocity>0 0 0 0 -0 0</velocity>
          <acceleration>0 0 0 0 -0 0</acceleration>
          <wrench>0 0 0 0 -0 0</wrench>
        </link>
      </model>
      <model name='obj_6'>
        <pose frame=''>-5.27395 1.69172 0 0 0 -0.442451</pose>
        <scale>1 1 1</scale>
        <link name='chassis'>
          <pose frame=''>-5.27395 1.69172 0.5 -1.5708 -0 -0.442451</pose>
          <velocity>0 0 0 0 -0 0</velocity>
          <acceleration>0 0 0 0 -0 0</acceleration>
          <wrench>0 0 0 0 -0 0</wrench>
        </link>
      </model>
      <model name='obj_7'>
        <pose frame=''>-3.52041 6.083 0 0 0 -0.442451</pose>
        <scale>1 1 1</scale>
        <link name='chassis'>
          <pose frame=''>-3.52041 6.083 0.5 -1.5708 -0 -0.442451</pose>
          <velocity>0 0 0 0 -0 0</velocity>
          <acceleration>0 0 0 0 -0 0</acceleration>
          <wrench>0 0 0 0 -0 0</wrench>
        </link>
      </model>
      <model name='obj_8'>
        <pose frame=''>-2.57853 7.20392 0 0 0 -0.442451</pose>
        <scale>1 1 1</scale>
        <link name='chassis'>
          <pose frame=''>-2.57853 7.20392 0.5 -1.5708 -0 -0.442451</pose>
          <velocity>0 0 0 0 -0 0</velocity>
          <acceleration>0 0 0 0 -0 0</acceleration>
          <wrench>0 0 0 0 -0 0</wrench>
        </link>
      </model>
      <model name='obj_9'>
        <pose frame=''>1.50359 2.43518 0 0 0 -0.442451</pose>
        <scale>1 1 1</scale>
        <link name='chassis'>
          <pose frame=''>1.50359 2.43518 0.5 -1.5708 -0 -0.442451</pose>
          <velocity>0 0 0 0 -0 0</velocity>
          <acceleration>0 0 0 0 -0 0</acceleration>
          <wrench>0 0 0 0 -0 0</wrench>
        </link>
      </model>
      <model name='wall_1_0'>
        <pose frame=''>7.82204 -5.25957 0 0 -0 2.67259</pose>
        <scale>1 1 1</scale>
        <link name='chassis'>
          <pose frame=''>7.82204 -5.25957 0.5 0 -0 2.67259</pose>
          <velocity>0 0 0 0 -0 0</velocity>
          <acceleration>0 0 0 0 -0 0</acceleration>
          <wrench>0 0 0 0 -0 0</wrench>
        </link>
      </model>
      <model name='wall_1_1'>
        <pose frame=''>1.3903 -1.2272 0 0 -0 2.05311</pose>
        <scale>1 1 1</scale>
        <link name='chassis'>
          <pose frame=''>1.3903 -1.2272 0.5 0 -0 2.05311</pose>
          <velocity>0 0 0 0 -0 0</velocity>
          <acceleration>0 0 0 0 -0 0</acceleration>
          <wrench>0 0 0 0 -0 0</wrench>
        </link>
      </model>
      <model name='wall_1_2'>
        <pose frame=''>-3.13099 -6.07933 0 0 0 -0.460154</pose>
        <scale>1 1 1</scale>
        <link name='chassis'>
          <pose frame=''>-3.13099 -6.07933 0.5 0 0 -0.460154</pose>
          <velocity>0 0 0 0 -0 0</velocity>
          <acceleration>0 0 0 0 -0 0</acceleration>
          <wrench>0 0 0 0 -0 0</wrench>
        </link>
      </model>
      <model name='wall_1_3'>
        <pose frame=''>-2.57759 1.72433 0 0 -0 0.070811</pose>
        <scale>1 1 1</scale>
        <link name='chassis'>
          <pose frame=''>-2.57759 1.72433 0.5 0 -0 0.070811</pose>
          <velocity>0 0 0 0 -0 0</velocity>
          <acceleration>0 0 0 0 -0 0</acceleration>
          <wrench>0 0 0 0 -0 0</wrench>
        </link>
      </model>
      <model name='wall_1_4'>
        <pose frame=''>5.23467 6.34425 0 0 -0 2.93807</pose>
        <scale>1 1 1</scale>
        <link name='chassis'>
          <pose frame=''>5.23467 6.34425 0.5 0 -0 2.93807</pose>
          <velocity>0 0 0 0 -0 0</velocity>
          <acceleration>0 0 0 0 -0 0</acceleration>
          <wrench>0 0 0 0 -0 0</wrench>
        </link>
      </model>
      <model name='wall_2_0'>
        <pose frame=''>-0.614454 -5.61156 0 0 -0 0.955773</pose>
        <scale>1 1 1</scale>
        <link name='chassis'>
          <pose frame=''>-0.614454 -5.61156 0.5 0 -0 0.955773</pose>
          <velocity>0 0 0 0 -0 0</velocity>
          <acceleration>0 0 0 0 -0 0</acceleration>
          <wrench>0 0 0 0 -0 0</wrench>
        </link>
      </model>
      <model name='wall_2_1'>
        <pose frame=''>-5.53819 4.78923 0 0 -0 3.07081</pose>
        <scale>1 1 1</scale>
        <link name='chassis'>
          <pose frame=''>-5.53819 4.78923 0.5 0 -0 3.07081</pose>
          <velocity>0 0 0 0 -0 0</velocity>
          <acceleration>0 0 0 0 -0 0</acceleration>
          <wrench>0 0 0 0 -0 0</wrench>
        </link>
      </model>
      <model name='wall_2_2'>
        <pose frame=''>5.2617 4.66455 0 0 0 -0.442451</pose>
        <scale>1 1 1</scale>
        <link name='chassis'>
          <pose frame=''>5.2617 4.66455 0.5 0 0 -0.442451</pose>
          <velocity>0 0 0 0 -0 0</velocity>
          <acceleration>0 0 0 0 -0 0</acceleration>
          <wrench>0 0 0 0 -0 0</wrench>
        </link>
      </model>
      <model name='wall_3_0'>
        <pose frame=''>-2.28394 -1.55685 0 0 -0 0.238958</pose>
        <scale>1 1 1</scale>
        <link name='chassis'>
          <pose frame=''>-2.28394 -1.55685 0.5 0 -0 0.238958</pose>
          <velocity>0 0 0 0 -0 0</velocity>
          <acceleration>0 0 0 0 -0 0</acceleration>
          <wrench>0 0 0 0 -0 0</wrench>
        </link>
      </model>
      <model name='wall_3_1'>
        <pose frame=''>-4.257 6.98275 0 0 -0 2.25666</pose>
        <scale>1 1 1</scale>
        <link name='chassis'>
          <pose frame=''>-4.257 6.98275 0.5 0 -0 2.25666</pose>
          <velocity>0 0 0 0 -0 0</velocity>
          <acceleration>0 0 0 0 -0 0</acceleration>
          <wrench>0 0 0 0 -0 0</wrench>
        </link>
      </model>
      <light name='sun'>
        <pose frame=''>0 0 10 0 -0 0</pose>
      </light>
    </state>
    <gui fullscreen='0'>
      <camera name='user_camera'>
        <pose frame=''>27.6414 -24.8173 29.3391 0 0.747643 2.3402</pose>
        <view_controller>orbit</view_controller>
        <projection_type>perspective</projection_type>
      </camera>
    </gui>
  </world>
</sdf>
